<?xml version="1.0"?>
<robot name="smartpal5">

	<!-- ==================== Planar joint ==================== -->
	
    <link name="start_position"/>

    <joint name="world_x_joint" type="prismatic">
        <parent link="start_position"/>
        <child link="world_x_link"/>
        <origin xyz="0 0 0" rpy="0 0 0"/>
        <limit effort="1000.0" lower="-5." upper="5." velocity="0.5"/>
    </joint>

    <link name="world_x_link"/>

    <joint name="world_y_joint" type="prismatic">
		<parent link="world_x_link"/>
		<child link="world_y_link"/>
		<origin xyz="0 0 0" rpy="0 0 1.57075"/>
        <limit effort="1000.0" lower="-5." upper="5." velocity="0.5"/>
    </joint>

    <link name="world_y_link"/>

    <joint name="world_theta_joint" type="continuous">
		<parent link="world_y_link"/>
		<child link="base_footprint"/>
		<origin xyz="0 0 0" rpy="0 0 -1.57075"/>
        <axis xyz="0 0 1"/>
	</joint>

    <link name="base_footprint"/>

	<joint name="base_footprint_joint" type="fixed">  
        <parent link="base_footprint"/>
		<child link="base_link"/>
		<origin xyz="0 0 0" rpy="0 0 0"/>
	</joint>

	<!-- ==================== Vehicle ==================== -->

	<link name="base_link"> <!-- Vehicle -->
		<visual>
			<geometry>
				<mesh filename="package://smartpal5_description/meshes/visual/Pal5_body_vehicle.dae"/>
			</geometry>
			<origin xyz="0 0 0" rpy="0 0 0"/> <!-- Offset for wheels already included in the mesh definition -->
			<material name="grey"/>
		</visual>
		<collision>
			<geometry>
				<mesh filename="package://smartpal5_description/meshes/collision/Pal5_body_vehicle.dae"/>
			</geometry>
			<origin xyz="0 0 0" rpy="0 0 0"/>
		</collision>
		<inertial>
			<origin xyz="0 0 0.0375" rpy="0 0 0"/>
			<mass value="27"/>
			<inertia ixx="1.0" ixy="0.0" ixz="0.0" iyy="1.0" iyz="0.0" izz="1.0"/>
		</inertial>
	</link>

	<!-- ==================== Vehicle - Lumbar Joint ==================== -->

	<joint name="vehicle__lumbar_j1_joint" type="revolute">
		<parent link="base_link"/> <!-- Vehicle -->
		<child link="lumbar_j1_link"/>
		<origin xyz="0 0 0.4365" rpy="-1.57075 0 0"/>
		<axis xyz="0 0 1"/>
		<limit lower="-0.2" upper="0.00872664625997165" effort="100.0" velocity="1.0"/>
	</joint>

	<!-- ==================== Lumbar ==================== -->

	<link name="lumbar_j1_link">
		<visual>
			<geometry>
				<mesh filename="package://smartpal5_description/meshes/visual/Pal5_body_lumbar-J1.dae"/>
			</geometry>
			<origin xyz="0 0 0" rpy="0 0 0"/>
			<material name="grey"/>
		</visual>
		<collision>
			<geometry>
				<mesh filename="package://smartpal5_description/meshes/collision/Pal5_body_lumbar-J1.dae"/>
			</geometry>
			<origin xyz="0 0 0" rpy="0 0 0"/>
		</collision>
		<inertial>
			<origin xyz="0 0 -0.1" rpy="0 0 0"/>
			<mass value="6"/>
			<inertia ixx="1.0" ixy="0.0" ixz="0.0" iyy="1.0" iyz="0.0" izz="1.0"/>
		</inertial>
	</link>

	<joint name="lumbar_j1__lumbar_j2_joint" type="revolute">
		<parent link="lumbar_j1_link"/>
		<child link="lumbar_j2_link"/>
		<origin xyz="0 -0.21 0" rpy="0 0 0"/>
		<axis xyz="0 0 1"/>
		<limit lower="-0.00872664625997165" upper="2.10312174865317" effort="100.0" velocity="1.0"/>
	</joint>

	<link name="lumbar_j2_link">
		<visual>
			<geometry>
				<mesh filename="package://smartpal5_description/meshes/visual/Pal5_body_lumbar-J2.dae"/>
			</geometry>
			<origin rpy="0 0 0" xyz="0 0 0"/>
			<material name="grey"/>
		</visual>
		<collision>
			<geometry>
				<mesh filename="package://smartpal5_description/meshes/collision/Pal5_body_lumbar-J2.dae"/>
			</geometry>
			<origin rpy="0 0 0" xyz="0 0 0"/>
		</collision>
		<inertial>
			<origin xyz="0.11 0 0.25" rpy="0 0 0"/>
			<mass value="30"/>
			<inertia ixx="1.0" ixy="0.0" ixz="0.0" iyy="1.0" iyz="0.0" izz="1.0"/>
		</inertial>
	</link>

    <!-- ==================== Lumbar - RGBD Camera Joint ==================== -->

    <!--change fixed->continuous-->
    <joint name="lumbar_j2__head_camera_joint" type="continuous">
		<parent link="lumbar_j2_link"/>
		<child link="camera_link"/>
		<origin xyz="0.02 -0.7 0" rpy="1.57075 0 0"/>			
	</joint>

    <!-- ==================== RGBD Camera ==================== -->

    <link name="camera_link">
		<visual>
			<geometry>
				<box size="0.03 0.15 0.05"/>
			</geometry>
			<origin xyz="0 0 0" rpy="0 0 0"/>
			<material name="grey"/>
		</visual>
		<collision>
			<geometry>
				<box size="0.05 0.2 0.08"/>
			</geometry>
			<origin xyz="0 0 0" rpy="0 0 0"/>
		</collision>
		<inertial>
		    <origin xyz="0 0 0" rpy="0 0 0"/>
			<mass value="0.5"/>
			<inertia ixx="1.0" ixy="0.0" ixz="0.0" iyy="1.0" iyz="0.0" izz="1.0"/>
		</inertial>
	</link>

    <!--joint name="camera_orientation" type="fixed">
        <parent link="camera_link"/>
        <child link="camera_oriented_link"/>
		<origin xyz="0 0 0" rpy="0 -1.57075 0"/>	
    </joint>

    <link name="camera_oriented_link"/-->


	<!-- ==================== Lumbar - Left Arm Joint ==================== -->

	<joint name="lumbar_j2__leftArm_j1_joint" type="revolute">
		<parent link="lumbar_j2_link"/>
		<child link="leftArm_j1_link"/>
		<origin xyz="-0.025 -0.480 0.200" rpy="3.14159 0 0"/>
		<axis xyz="0 0 1"/>
		<limit lower="-0.7679" upper="3.1066" effort="100.0" velocity="1.0"/>
	</joint>

	<!-- ==================== Left Arm ==================== -->

	<link name="leftArm_j1_link">
		<visual>
			<geometry>
				<mesh filename="package://smartpal5_description/meshes/visual/Pal5_leftArm_J1.dae"/>
			</geometry>
			<origin xyz="0 0 0" rpy="0 0 0"/>
			<material name="grey"/>
		</visual>
		<collision>
			<geometry>
				<mesh filename="package://smartpal5_description/meshes/collision/Pal5_leftArm_J1.dae"/>
			</geometry>
			<origin xyz="0 0 0" rpy="0 0 0"/>
		</collision>
		<inertial>
			<origin xyz="0 0 -0.1" rpy="0 0 0"/>
			<mass value="0.6"/>
			<inertia ixx="1.0" ixy="0.0" ixz="0.0" iyy="1.0" iyz="0.0" izz="1.0"/>
		</inertial>
	</link>

	<joint name="leftArm_j1__leftArm_j2_joint" type="revolute">
		<parent link="leftArm_j1_link"/>
		<child link="leftArm_j2_link"/>
		<origin xyz="0 0 0" rpy="1.57075 3.14159 1.57075"/>
		<axis xyz="0 0 1"/>
		<limit lower="-0.2443" upper="1.9024" effort="100.0" velocity="1.0"/>
	</joint>

	<link name="leftArm_j2_link">
		<visual>
			<geometry>
				<mesh filename="package://smartpal5_description/meshes/visual/Pal5_leftArm_J2.dae"/>
			</geometry>
			<origin rpy="0 0 0" xyz="0 0 0"/>
			<material name="grey"/>
		</visual>
		<collision>
			<geometry>
				<mesh filename="package://smartpal5_description/meshes/collision/Pal5_leftArm_J2.dae"/>
			</geometry>
			<origin rpy="0 0 0" xyz="0 0 0"/>
		</collision>
		<inertial>
			<origin xyz="0 0 -0.1" rpy="0 0 0"/>
			<mass value="0.6"/>
			<inertia ixx="1.0" ixy="0.0" ixz="0.0" iyy="1.0" iyz="0.0" izz="1.0"/>
		</inertial>
	</link>

	<joint name="leftArm_j2__leftArm_j3_joint" type="revolute">
		<parent link="leftArm_j2_link"/>
		<child link="leftArm_j3_link"/>
		<origin xyz="0 0 0" rpy="1.57075 1.57075 1.57075"/>
		<axis xyz="0 0 1"/>
		<limit lower="-2.0769" upper="2.0769" effort="100.0" velocity="1.0"/>
	</joint>

	<link name="leftArm_j3_link">
		<visual>
			<geometry>
				<mesh filename="package://smartpal5_description/meshes/visual/Pal5_leftArm_J3.dae"/>
			</geometry>
			<origin rpy="0 0 0" xyz="0 0 0"/>
			<material name="grey"/>
		</visual>
		<collision>
			<geometry>
				<mesh filename="package://smartpal5_description/meshes/collision/Pal5_leftArm_J3.dae"/>
			</geometry>
			<origin rpy="0 0 0" xyz="0 0 0"/>
		</collision>
		<inertial>
			<origin xyz="0 0 0" rpy="0 0 0"/>
			<mass value="1"/>
			<inertia ixx="1.0" ixy="0.0" ixz="0.0" iyy="1.0" iyz="0.0" izz="1.0"/>
		</inertial>
	</link>

	<joint name="leftArm_j3__leftArm_j4_joint" type="revolute">
		<parent link="leftArm_j3_link"/>
		<child link="leftArm_j4_link"/>
		<origin xyz="-0.02 0.0 0.25" rpy="-1.57075 0 3.14159"/>
		<axis xyz="0 0 1"/>
		<limit lower="-0.0174" upper="2.2514" effort="100.0" velocity="1.0"/>
	</joint>

	<link name="leftArm_j4_link">
		<visual>
			<geometry>
				<mesh filename="package://smartpal5_description/meshes/visual/Pal5_leftArm_J4.dae"/>
			</geometry>
			<origin rpy="0 0 0" xyz="0 0 0"/>
			<material name="grey"/>
		</visual>
		<collision>
			<geometry>
				<mesh filename="package://smartpal5_description/meshes/collision/Pal5_leftArm_J4.dae"/>
			</geometry>
			<origin rpy="0 0 0" xyz="0 0 0"/>
		</collision>
		<inertial>
			<origin xyz="0 0 -0.3" rpy="0 0 0"/>
			<mass value="0.6"/>
			<inertia ixx="1.0" ixy="0.0" ixz="0.0" iyy="1.0" iyz="0.0" izz="1.0"/>
		</inertial>
	</link>

	<joint name="leftArm_j4__leftArm_j5_joint" type="revolute">
		<parent link="leftArm_j4_link"/>
		<child link="leftArm_j5_link"/>
		<origin xyz="-0.02 0.0 0.0" rpy="1.57075 0 0"/>
		<axis xyz="0 0 1"/>
		<limit lower="-2.0769" upper="2.0769" effort="100.0" velocity="1.0"/>
	</joint>

	<link name="leftArm_j5_link">
		<visual>
			<geometry>
				<mesh filename="package://smartpal5_description/meshes/visual/Pal5_leftArm_J5.dae"/>
			</geometry>
			<origin rpy="0 0 0" xyz="0 0 0"/>
			<material name="grey"/>
		</visual>
		<collision>
			<geometry>
				<mesh filename="package://smartpal5_description/meshes/collision/Pal5_leftArm_J5.dae"/>
			</geometry>
			<origin rpy="0 0 0" xyz="0 0 0"/>
		</collision>
		<inertial>
			<origin xyz="0 0 0.1" rpy="0 0 0"/>
			<mass value="0.4"/>
			<inertia ixx="1.0" ixy="0.0" ixz="0.0" iyy="1.0" iyz="0.0" izz="1.0"/>
		</inertial>
	</link>

	<joint name="leftArm_j5__leftArm_j6_joint" type="revolute">
		<parent link="leftArm_j5_link"/>
		<child link="leftArm_j6_link"/>
		<origin xyz="0.0 0.0 0.28" rpy="-1.57075 1.57075 0"/>
		<axis xyz="0 0 1"/>
		<limit lower="-0.2617" upper="0.7504" effort="100.0" velocity="1.0"/>
	</joint>

	<link name="leftArm_j6_link">
		<visual>
			<geometry>
				<mesh filename="package://smartpal5_description/meshes/visual/Pal5_leftArm_J6.dae"/>
			</geometry>
			<origin rpy="0 0 0" xyz="0 0 0"/>
			<material name="grey"/>
		</visual>
		<collision>
			<geometry>
				<mesh filename="package://smartpal5_description/meshes/collision/Pal5_leftArm_J6.dae"/>
			</geometry>
			<origin rpy="0 0 0" xyz="0 0 0"/>
		</collision>
		<inertial>
			<origin xyz="-0.1 0 0" rpy="0 0 0"/>
			<mass value="0.4"/>
			<inertia ixx="1.0" ixy="0.0" ixz="0.0" iyy="1.0" iyz="0.0" izz="1.0"/>
		</inertial>
	</link>

	<joint name="leftArm_j6__leftArm_j7_joint" type="revolute">
		<parent link="leftArm_j6_link"/>
		<child link="leftArm_j7_link"/>
		<origin xyz="0.0 0.0 0" rpy="1.57075 3.14159 0"/>
		<axis xyz="0 0 1"/>
		<limit lower="0" upper="0.5" effort="100.0" velocity="1.0"/>
	</joint>

	<link name="leftArm_j7_link">
		<visual>
			<geometry>
				<mesh filename="package://smartpal5_description/meshes/visual/Pal5_leftArm_J7.dae"/>
			</geometry>
			<origin rpy="0 0 0" xyz="0 0 0"/>
			<material name="grey"/>
		</visual>
		<collision>
			<geometry>
				<mesh filename="package://smartpal5_description/meshes/collision/Pal5_leftArm_J7.dae"/>
			</geometry>
			<origin rpy="0 0 0" xyz="0 0 0"/>
		</collision>
		<inertial>
			<origin xyz="0 0 -0.1" rpy="0 0 0"/>
			<mass value="0.4"/>
			<inertia ixx="1.0" ixy="0.0" ixz="0.0" iyy="1.0" iyz="0.0" izz="1.0"/>
		</inertial>
	</link>

	<!-- ==================== Left Arm - Left Gripper Joint ==================== -->
 	<!--change fixed->continuous-->
	<joint name="leftArm_j7__leftGripper_joint" type="continuous">
		<parent link="leftArm_j7_link"/>
		<child link="leftGripper_link"/>
		<origin xyz="0.056 0 0" rpy="3.14159 3.14159 1.57075"/>
		<axis xyz="0 0 1"/>
	</joint>

	<!-- ==================== Left Gripper ==================== -->

	<link name="leftGripper_link">
		<visual>
			<geometry>
				<mesh filename="package://smartpal5_description/meshes/visual/Pal5_leftGripper_gripper.dae"/>
			</geometry>
			<origin rpy="0 0 0" xyz="0 0 0"/>
			<material name="grey"/>
		</visual>
		<collision>
			<geometry>
				<mesh filename="package://smartpal5_description/meshes/collision/Pal5_leftGripper_gripper.dae"/>
			</geometry>
			<origin rpy="0 0 0" xyz="0 0 0"/>
		</collision>
		<inertial>
			<origin xyz="0 0 -0.1" rpy="0 0 0"/>
			<mass value="0.6"/>
			<inertia ixx="1.0" ixy="0.0" ixz="0.0" iyy="1.0" iyz="0.0" izz="1.0"/>
		</inertial>
	</link>

	<joint name="leftGripper__leftGripper_thumb_joint" type="revolute">
		<parent link="leftGripper_link"/>
		<child link="leftGripper_thumb_link"/>
		<origin xyz="0.027 0.042 0.0" rpy="0 0 0"/>
		<axis xyz="0 0 1"/>
		<limit lower="-1.0122" upper="0.1396" effort="100.0" velocity="1.0"/>
	</joint>

	<link name="leftGripper_thumb_link">
		<visual>
			<geometry>
				<mesh filename="package://smartpal5_description/meshes/visual/Pal5_leftGripper_g-thumb.dae"/>
			</geometry>
			<origin rpy="0 0 0" xyz="0 0 0"/>
			<material name="grey"/>
		</visual>
		<collision>
			<geometry>
				<mesh filename="package://smartpal5_description/meshes/collision/Pal5_leftGripper_g-thumb.dae"/>
			</geometry>
			<origin rpy="0 0 0" xyz="0 0 0"/>
		</collision>
		<inertial>
			<origin xyz="0 0 -0.1" rpy="0 0 0"/>
			<mass value="0.4"/>
			<inertia ixx="1.0" ixy="0.0" ixz="0.0" iyy="1.0" iyz="0.0" izz="1.0"/>
		</inertial>
	</link>

	<!-- ==================== Lumbar - Right Arm Joint ==================== -->

	<joint name="lumbar_j2__rightArm_j1_joint" type="revolute">
		<parent link="lumbar_j2_link"/>
		<child link="rightArm_j1_link"/>
		<origin xyz="-0.025 -0.480 -0.200" rpy="3.14159 0 0"/>
		<axis xyz="0 0 1"/>
		<limit lower="-0.7679" upper="3.1066" effort="100.0" velocity="1.0"/>
	</joint>

	<!-- ==================== Right Arm ==================== -->

	<link name="rightArm_j1_link">
		<visual>
			<geometry>
				<mesh filename="package://smartpal5_description/meshes/visual/Pal5_rightArm_J1.dae"/>
			</geometry>
			<origin xyz="0 0 0" rpy="0 0 0"/>
			<material name="grey"/>
		</visual>
		<collision>
			<geometry>
				<mesh filename="package://smartpal5_description/meshes/collision/Pal5_rightArm_J1.dae"/>
			</geometry>
			<origin xyz="0 0 0" rpy="0 0 0"/>
		</collision>
		<inertial>
			<origin xyz="0 0 -0.1" rpy="0 0 0"/>
			<mass value="0.6"/>
			<inertia ixx="1.0" ixy="0.0" ixz="0.0" iyy="1.0" iyz="0.0" izz="1.0"/>
		</inertial>
	</link>

	<joint name="rightArm_j1__rightArm_j2_joint" type="revolute">
		<parent link="rightArm_j1_link"/>
		<child link="rightArm_j2_link"/>
		<origin xyz="0 0 0" rpy="-1.57075 0 -1.57075"/>
		<axis xyz="0 0 1"/>
		<limit lower="-1.9024" upper="0.2443" effort="100.0" velocity="1.0"/>
	</joint>

	<link name="rightArm_j2_link">
		<visual>
			<geometry>
				<mesh filename="package://smartpal5_description/meshes/visual/Pal5_rightArm_J2.dae"/>
			</geometry>
			<origin rpy="0 0 0" xyz="0 0 0"/>
			<material name="grey"/>
		</visual>
		<collision>
			<geometry>
				<mesh filename="package://smartpal5_description/meshes/collision/Pal5_rightArm_J2.dae"/>
			</geometry>
			<origin rpy="0 0 0" xyz="0 0 0"/>
		</collision>
		<inertial>
			<origin xyz="0 0 -0.1" rpy="0 0 0"/>
			<mass value="0.6"/>
			<inertia ixx="1.0" ixy="0.0" ixz="0.0" iyy="1.0" iyz="0.0" izz="1.0"/>
		</inertial>
	</link>

	<joint name="rightArm_j2__rightArm_j3_joint" type="revolute">
		<parent link="rightArm_j2_link"/>
		<child link="rightArm_j3_link"/>
		<origin xyz="0 0 0" rpy="1.57075 1.57075 1.57075"/>
		<axis xyz="0 0 1"/>
		<limit lower="-2.0769" upper="2.0769" effort="100.0" velocity="1.0"/>
	</joint>

	<link name="rightArm_j3_link">
		<visual>
			<geometry>
				<mesh filename="package://smartpal5_description/meshes/visual/Pal5_rightArm_J3.dae"/>
			</geometry>
			<origin rpy="0 0 0" xyz="0 0 0"/>
			<material name="grey"/>
		</visual>
		<collision>
			<geometry>
				<mesh filename="package://smartpal5_description/meshes/collision/Pal5_rightArm_J3.dae"/>
			</geometry>
			<origin rpy="0 0 0" xyz="0 0 0"/>
		</collision>
		<inertial>
			<origin xyz="0 0 0" rpy="0 0 0"/>
			<mass value="1"/>
			<inertia ixx="1.0" ixy="0.0" ixz="0.0" iyy="1.0" iyz="0.0" izz="1.0"/>
		</inertial>
	</link>

	<joint name="rightArm_j3__rightArm_j4_joint" type="revolute">
		<parent link="rightArm_j3_link"/>
		<child link="rightArm_j4_link"/>
		<origin xyz="-0.02 0.0 0.25" rpy="-1.57075 0 3.14159"/>
		<axis xyz="0 0 1"/>
		<limit lower="-0.0174" upper="2.2514" effort="100.0" velocity="1.0"/>
	</joint>

	<link name="rightArm_j4_link">
		<visual>
			<geometry>
				<mesh filename="package://smartpal5_description/meshes/visual/Pal5_rightArm_J4.dae"/>
			</geometry>
			<origin rpy="0 0 0" xyz="0 0 0"/>
			<material name="grey"/>
		</visual>
		<collision>
			<geometry>
				<mesh filename="package://smartpal5_description/meshes/collision/Pal5_rightArm_J4.dae"/>
			</geometry>
			<origin rpy="0 0 0" xyz="0 0 0"/>
		</collision>
		<inertial>
			<origin xyz="0 0 -0.3" rpy="0 0 0"/>
			<mass value="0.6"/>
			<inertia ixx="1.0" ixy="0.0" ixz="0.0" iyy="1.0" iyz="0.0" izz="1.0"/>
		</inertial>
	</link>

	<joint name="rightArm_j4__rightArm_j5_joint" type="revolute">
		<parent link="rightArm_j4_link"/>
		<child link="rightArm_j5_link"/>
		<origin xyz="-0.02 0.0 0.0" rpy="1.57075 0 0"/>
		<axis xyz="0 0 1"/>
		<limit lower="-2.0769" upper="2.0769" effort="100.0" velocity="1.0"/>
	</joint>

	<link name="rightArm_j5_link">
		<visual>
			<geometry>
				<mesh filename="package://smartpal5_description/meshes/visual/Pal5_rightArm_J5.dae"/>
			</geometry>
			<origin rpy="0 0 0" xyz="0 0 0"/>
			<material name="grey"/>
		</visual>
		<collision>
			<geometry>
				<mesh filename="package://smartpal5_description/meshes/collision/Pal5_rightArm_J5.dae"/>
			</geometry>
			<origin rpy="0 0 0" xyz="0 0 0"/>
		</collision>
		<inertial>
			<origin xyz="0 0 0.1" rpy="0 0 0"/>
			<mass value="0.4"/>
			<inertia ixx="1.0" ixy="0.0" ixz="0.0" iyy="1.0" iyz="0.0" izz="1.0"/>
		</inertial>
	</link>

	<joint name="rightArm_j5__rightArm_j6_joint" type="revolute">
		<parent link="rightArm_j5_link"/>
		<child link="rightArm_j6_link"/>
		<origin xyz="0.0 0.0 0.28" rpy="-1.57075 1.57075 0"/>
		<axis xyz="0 0 1"/>
		<limit lower="-0.2617" upper="0.7504" effort="100.0" velocity="1.0"/>
	</joint>

	<link name="rightArm_j6_link">
		<visual>
			<geometry>
				<mesh filename="package://smartpal5_description/meshes/visual/Pal5_rightArm_J6.dae"/>
			</geometry>
			<origin rpy="0 0 0" xyz="0 0 0"/>
			<material name="grey"/>
		</visual>
		<collision>
			<geometry>
				<mesh filename="package://smartpal5_description/meshes/collision/Pal5_rightArm_J6.dae"/>
			</geometry>
			<origin rpy="0 0 0" xyz="0 0 0"/>
		</collision>
		<inertial>
			<origin xyz="-0.1 0 0" rpy="0 0 0"/>
			<mass value="0.4"/>
			<inertia ixx="1.0" ixy="0.0" ixz="0.0" iyy="1.0" iyz="0.0" izz="1.0"/>
		</inertial>
	</link>

	<joint name="rightArm_j6__rightArm_j7_joint" type="revolute">
		<parent link="rightArm_j6_link"/>
		<child link="rightArm_j7_link"/>
		<origin xyz="0.0 0.0 0" rpy="1.57075 3.14159 0"/>
		<axis xyz="0 0 1"/>
		<limit lower="-1.0122" upper="1.0" effort="100.0" velocity="1.0"/>
	</joint>

	<link name="rightArm_j7_link">
		<visual>
			<geometry>
				<mesh filename="package://smartpal5_description/meshes/visual/Pal5_rightArm_J7.dae"/>
			</geometry>
			<origin rpy="0 0 0" xyz="0 0 0"/>
			<material name="grey"/>
		</visual>
		<collision>
			<geometry>
				<mesh filename="package://smartpal5_description/meshes/collision/Pal5_rightArm_J7.dae"/>
			</geometry>
			<origin rpy="0 0 0" xyz="0 0 0"/>
		</collision>
		<inertial>
			<origin xyz="0 0 -0.1" rpy="0 0 0"/>
			<mass value="0.4"/>
			<inertia ixx="1.0" ixy="0.0" ixz="0.0" iyy="1.0" iyz="0.0" izz="1.0"/>
		</inertial>
	</link>

	<!-- ==================== Right Arm - Right Gripper Joint ==================== -->

	<!--change fixed->continuous-->
	<joint name="rightArm_j7__rightGripper_joint" type="continuous">
		<parent link="rightArm_j7_link"/>
		<child link="rightGripper_link"/>
		<origin xyz="0.056 0 0" rpy="3.14159 3.14159 3.14159"/>
		<axis xyz="0 0 1"/>
	</joint>

	<!-- ==================== Right Gripper ==================== -->

	<link name="rightGripper_link">
		<visual>
			<geometry>
				<mesh filename="package://smartpal5_description/meshes/visual/Pal5_rightGripper_gripper.dae"/>
			</geometry>
			<origin rpy="0 0 0" xyz="0 0 0"/>
			<material name="grey"/>
		</visual>
		<collision>
			<geometry>
				<mesh filename="package://smartpal5_description/meshes/collision/Pal5_rightGripper_gripper.dae"/>
			</geometry>
			<origin rpy="0 0 0" xyz="0 0 0"/>
		</collision>
		<inertial>
			<origin xyz="0 0 -0.1" rpy="0 0 0"/>
			<mass value="0.6"/>
			<inertia ixx="1.0" ixy="0.0" ixz="0.0" iyy="1.0" iyz="0.0" izz="1.0"/>
		</inertial>
	</link>

	<joint name="rightGripper__rightGripper_thumb_joint" type="revolute">
		<parent link="rightGripper_link"/>
		<child link="rightGripper_thumb_link"/>
		<origin xyz="0.042 0.027 0.0" rpy="0 0 -1.57075"/>
		<axis xyz="0 0 1"/>
		<limit lower="-0.1396" upper="1.0122" effort="100.0" velocity="1.0"/>
	</joint>

	<link name="rightGripper_thumb_link">
		<visual>
			<geometry>
				<mesh filename="package://smartpal5_description/meshes/visual/Pal5_rightGripper_g-thumb.dae"/>
			</geometry>
			<origin rpy="0 0 0" xyz="0 0 0"/>
			<material name="grey"/>
		</visual>
		<collision>
			<geometry>
				<mesh filename="package://smartpal5_description/meshes/collision/Pal5_rightGripper_g-thumb.dae"/>
			</geometry>
			<origin rpy="0 0 0" xyz="0 0 0"/>
		</collision>
		<inertial>
			<origin xyz="0 0 -0.1" rpy="0 0 0"/>
			<mass value="0.4"/>
			<inertia ixx="1.0" ixy="0.0" ixz="0.0" iyy="1.0" iyz="0.0" izz="1.0"/>
		</inertial>
    </link>


	<!-- ==================== Environment ==================== -->

  <joint name="world_joint" type="fixed">
    <parent link="start_position"/>
    <child link="floor928"/>
    <origin xyz="0 0 0" rpy="0 0 0"/>
  </joint>

  <link name="floor928">
    <visual>
      <geometry>
        <mesh filename="package://environmental_model/model/room/floor928.dae"/>
      </geometry>
      <origin rpy="0 0 0" xyz="0 0 0"/>
    </visual>
  </link>

  <link name="wall928">
    <visual>
      <geometry>
        <mesh filename="package://environmental_model/model/room/wall928.dae"/>
      </geometry>
      <origin rpy="0 0 0" xyz="0 0 0"/>
    </visual>
  </link>
  <joint name="floor_to_wall" type="fixed">
    <parent link="floor928"/>
    <child link="wall928"/>
    <origin xyz="0 0 0"/>
  </joint>

  <link name="bed">
    <visual>
      <geometry>
        <mesh filename="package://environmental_model/model/furniture/bed.dae"/>
      </geometry>
      <origin rpy="0 0 1.57" xyz="1.05 0 0"/>
    </visual>
  </link>
  <joint name="floor_to_bed" type="fixed">
    <parent link="floor928"/>
    <child link="bed"/>
    <origin xyz="0 0 0"/>
  </joint>

  <link name="big_sofa">
    <visual>
      <geometry>
        <mesh filename="package://environmental_model/model/furniture/big_sofa.dae"/>
      </geometry>
      <origin rpy="0 0 0" xyz="6.3 3.7 0"/>
    </visual>s
  </link>
  <joint name="floor_to_big_sofa" type="fixed">
    <parent link="floor928"/>
    <child link="big_sofa"/>
    <origin xyz="0 0 0"/>
  </joint>

  <link name="desk1">
    <visual>
      <geometry>
        <mesh filename="package://environmental_model/model/furniture/desk1.dae"/>
      </geometry>
      <origin rpy="0 0 0" xyz="0 3.9 0"/>
    </visual>
  </link>
  <joint name="floor_to_desk1" type="fixed">
    <parent link="floor928"/>
    <child link="desk1"/>
    <origin xyz="0 0 0"/>
  </joint>

  <link name="desk2">
    <visual>
      <geometry>
        <mesh filename="package://environmental_model/model/furniture/desk2.dae"/>
      </geometry>
      <origin rpy="0 0 0" xyz="3.4 2.1 0"/>
    </visual>
  </link>
  <joint name="floor_to_desk2" type="fixed">
    <parent link="floor928"/>
    <child link="desk2"/>
    <origin xyz="0 0 0"/>
  </joint>

  <link name="tv">
    <visual>
      <geometry>
        <mesh filename="package://environmental_model/model/furniture/tv.dae"/>
      </geometry>
      <origin rpy="0 0 3.14" xyz="7.6 0.4 0.5"/>
    </visual>
  </link>
  <joint name="floor_to_tv" type="fixed">
    <parent link="floor928"/>
    <child link="tv"/>
    <origin xyz="0 0 0"/>
  </joint>

  <link name="tv_table">
    <visual>
      <geometry>
        <mesh filename="package://environmental_model/model/furniture/tv_table.dae"/>
      </geometry>
      <origin rpy="0 0 3.14" xyz="7.6 0.4 0"/>
    </visual>
  </link>
  <joint name="floor_to_tv_table" type="fixed">
    <parent link="floor928"/>
    <child link="tv_table"/>
    <origin xyz="0 0 0"/>
  </joint>

  <link name="mini_sofa">
    <visual>
      <geometry>
        <mesh filename="package://environmental_model/model/furniture/mini_sofa.dae"/>
      </geometry>
      <origin rpy="0 0 0" xyz="7.45 2.75 0"/>
    </visual>
  </link>
  <joint name="floor_to_mini_sofa" type="fixed">
    <parent link="floor928"/>
    <child link="mini_sofa"/>
    <origin xyz="0 0 0"/>
  </joint>

  <link name="small_table">
    <visual>
      <geometry>
        <mesh filename="package://environmental_model/model/furniture/small_table.dae"/>
      </geometry>
      <origin rpy="0 0 0" xyz="6.3 2.7 0"/>
    </visual>
  </link>
  <joint name="floor_to_small_table" type="fixed">
    <parent link="floor928"/>
    <child link="small_table"/>
    <origin xyz="0 0 0"/>
  </joint>

 <link name="partition1">
    <visual>
      <geometry>
        <mesh filename="package://environmental_model/model/furniture/partition1050x900.dae"/>
      </geometry>
      <origin rpy="0 0 0" xyz="4 3.008 0"/>
    </visual>
  </link>
  <joint name="floor_to_partition1" type="fixed">
    <parent link="floor928"/>
    <child link="partition1"/>
    <origin xyz="0 0 0"/>
  </joint>

  <link name="partition2">
    <visual>
      <geometry>
        <mesh filename="package://environmental_model/model/furniture/partition1050x700.dae"/>
      </geometry>
      <origin rpy="0 0 -1.57" xyz="4 3 0"/>
    </visual>
  </link>
  <joint name="floor_to_partition2" type="fixed">
    <parent link="floor928"/>
    <child link="partition2"/>
    <origin xyz="0 0 0"/>
  </joint>

  <link name="partition3">
    <visual>
      <geometry>
        <mesh filename="package://environmental_model/model/furniture/partition1050x900.dae"/>
      </geometry>
      <origin rpy="0 0 -1.57" xyz="4 2.4 0"/>
    </visual>
  </link>
  <joint name="floor_to_partition3" type="fixed">
    <parent link="floor928"/>
    <child link="partition3"/>
    <origin xyz="0 0 0"/>
  </joint>

  <link name="shelf1">
    <visual>
      <geometry>
        <mesh filename="package://environmental_model/model/furniture/shelf1.dae"/>
      </geometry>
      <origin rpy="0 0 1.57" xyz="4.4 1.6 0"/>
    </visual>
  </link>
  <joint name="floor_to_shelf1" type="fixed">
    <parent link="floor928"/>
    <child link="shelf1"/>
    <origin xyz="0 0 0"/>
  </joint>

  <link name="big_shelf">
    <visual>
      <geometry>
        <mesh filename="package://environmental_model/model/furniture/big_shelf.dae"/>
      </geometry>
      <origin rpy="0 0 0" xyz="1.5 4.1 0"/>
    </visual>
  </link>
  <joint name="floor_to_big_shelf" type="fixed">
    <parent link="floor928"/>
    <child link="big_shelf"/>
    <origin xyz="0 0 0"/>
  </joint>

  <link name="chair_table">
    <visual>
      <geometry>
        <mesh filename="package://environmental_model/model/furniture/chair1.dae"/>
      </geometry>
      <origin rpy="0 0 3.14" xyz="3.5 2.7 0"/>
    </visual>
  </link>
  <joint name="floor_to_chair_table" type="fixed">
    <parent link="floor928"/>
    <child link="chair_table"/>
    <origin xyz="0 0 0"/>
  </joint>

  <link name="chair_desk">
    <visual>
      <geometry>
        <mesh filename="package://environmental_model/model/furniture/chair1.dae"/>
      </geometry>
      <origin rpy="0 0 0" xyz="0.72 3.9 0"/>
    </visual>
  </link>
  <joint name="floor_to_chair_desk" type="fixed">
    <parent link="floor928"/>
    <child link="chair_desk"/>
    <origin xyz="0 0 0"/>
  </joint>

  <link name="bottle">
    <visual>
      <geometry>
        <mesh filename="package://environmental_model/model/object/greentea_bottle.dae"/>
      </geometry>
      <origin rpy="0 0 0" xyz="1.8 4.4 1"/>
    </visual>
  </link>
  <joint name="floor_to_bottle" type="fixed">
    <parent link="floor928"/>
    <child link="bottle"/>
    <origin xyz="0 0 0"/>
  </joint>

  <link name="fridge">
    <visual>
      <geometry>
        <mesh filename="package://environmental_model/model/refrigerator/refrigerator.dae"/>
      </geometry>
      <origin rpy="0 0 1.57" xyz="4.35 2.5 0.6"/>
    </visual>
  </link>
  <joint name="floor_to_fridge" type="fixed">
    <parent link="floor928"/>
    <child link="fridge"/>
    <origin xyz="0 0 0"/>
  </joint>

</robot>
